import * as core from '@actions/core';
import { Octokit } from 'octokit';
import { truncateOutput } from './truncateOutput.js';
import { GitHubEvent, RepoContext } from './types.js';

/**
 * Posts a comment to the issue or PR with retry mechanism for transient errors.
 */
export async function postComment(
  octokit: Octokit,
  repo: RepoContext,
  event: GitHubEvent,
  body: string,
  maxRetries = 3,
  retryDelay = 1000
): Promise<void> {
  let retries = 0;

  while (true) {
    try {
      if ('issue' in event) {
        // For regular issues and PR conversation comments
        const issueNumber = event.issue.number;
        await octokit.rest.issues.createComment({
          ...repo,
          issue_number: issueNumber,
          body: truncateOutput(body),
        });
        return;
      } else if ('pull_request' in event) {
        const prNumber = event.pull_request.number;
        const commentId = event.comment.id;
        const inReplyTo = event.comment.in_reply_to_id;

        try {
          await octokit.rest.pulls.createReplyForReviewComment({
            ...repo,
            pull_number: prNumber,
            comment_id: inReplyTo ?? commentId,
            body: truncateOutput(body),
          });
          return;

        } catch (commentError) {
          core.warning(`‚ö†Ô∏è failed to check if comment is top-level: ${commentError instanceof Error ? commentError.message : commentError}`);
          core.info(`üîÑ falling back to creating a regular pr comment instead of a reply`);
          await octokit.rest.issues.createComment({
            ...repo,
            issue_number: prNumber,
            body: truncateOutput(body),
          });
          return; 
        }
      }
      return; // If we get here without an event match, just return
    } catch (error) {
      // Check if we should retry
      const errorMessage = error instanceof Error ? error.message : String(error);
      const isRetryableError = errorMessage.includes('EPIPE') ||
        errorMessage.includes('ECONNRESET') ||
        errorMessage.includes('ETIMEDOUT') ||
        errorMessage.includes('timeout') ||
        errorMessage.includes('network');

      if (isRetryableError && retries < maxRetries) {
        retries++;
        const waitTime = retryDelay * retries;
        core.warning(`üåê network error when posting comment: ${errorMessage}. retrying ${retries}/${maxRetries} in ${waitTime}ms...`);

        await new Promise(resolve => setTimeout(resolve, waitTime));
        continue; // Try again
      }

      core.error(`‚ùå failed to post comment after ${retries} retries: ${errorMessage}`);
      return;
    }
  }
}
